2023-07-11 08:47:10,170 INFO    StreamThr :12080 [internal.py:wandb_internal():86] W&B internal server running at pid: 12080, started at: 2023-07-11 08:47:10.169082
2023-07-11 08:47:10,171 DEBUG   HandlerThread:12080 [handler.py:handle_request():144] handle_request: status
2023-07-11 08:47:10,250 INFO    WriterThread:12080 [datastore.py:open_for_write():85] open: F:\Project\PythonProject\ultralytics\wandb\run-20230711_084710-k44t7nmw\run-k44t7nmw.wandb
2023-07-11 08:47:10,250 DEBUG   SenderThread:12080 [sender.py:send():369] send: header
2023-07-11 08:47:10,300 DEBUG   SenderThread:12080 [sender.py:send():369] send: run
2023-07-11 08:47:15,332 DEBUG   HandlerThread:12080 [handler.py:handle_request():144] handle_request: keepalive
2023-07-11 08:47:20,368 DEBUG   HandlerThread:12080 [handler.py:handle_request():144] handle_request: keepalive
2023-07-11 08:47:25,407 DEBUG   HandlerThread:12080 [handler.py:handle_request():144] handle_request: keepalive
2023-07-11 08:47:30,446 DEBUG   HandlerThread:12080 [handler.py:handle_request():144] handle_request: keepalive
2023-07-11 08:47:35,518 DEBUG   HandlerThread:12080 [handler.py:handle_request():144] handle_request: keepalive
2023-07-11 08:47:40,556 DEBUG   HandlerThread:12080 [handler.py:handle_request():144] handle_request: keepalive
2023-07-11 08:47:43,772 INFO    SenderThread:12080 [retry.py:__call__():172] Retry attempt failed:
Traceback (most recent call last):
  File "D:\DevTools\Anaconda\envs\yolov8\lib\site-packages\urllib3\connection.py", line 174, in _new_conn
    conn = connection.create_connection(
  File "D:\DevTools\Anaconda\envs\yolov8\lib\site-packages\urllib3\util\connection.py", line 95, in create_connection
    raise err
  File "D:\DevTools\Anaconda\envs\yolov8\lib\site-packages\urllib3\util\connection.py", line 85, in create_connection
    sock.connect(sa)
socket.timeout: timed out

During handling of the above exception, another exception occurred:

Traceback (most recent call last):
  File "D:\DevTools\Anaconda\envs\yolov8\lib\site-packages\urllib3\connectionpool.py", line 703, in urlopen
    httplib_response = self._make_request(
  File "D:\DevTools\Anaconda\envs\yolov8\lib\site-packages\urllib3\connectionpool.py", line 386, in _make_request
    self._validate_conn(conn)
  File "D:\DevTools\Anaconda\envs\yolov8\lib\site-packages\urllib3\connectionpool.py", line 1042, in _validate_conn
    conn.connect()
  File "D:\DevTools\Anaconda\envs\yolov8\lib\site-packages\urllib3\connection.py", line 363, in connect
    self.sock = conn = self._new_conn()
  File "D:\DevTools\Anaconda\envs\yolov8\lib\site-packages\urllib3\connection.py", line 179, in _new_conn
    raise ConnectTimeoutError(
urllib3.exceptions.ConnectTimeoutError: (<urllib3.connection.HTTPSConnection object at 0x000001A589FA28B0>, 'Connection to api.wandb.ai timed out. (connect timeout=10)')

During handling of the above exception, another exception occurred:

Traceback (most recent call last):
  File "D:\DevTools\Anaconda\envs\yolov8\lib\site-packages\requests\adapters.py", line 489, in send
    resp = conn.urlopen(
  File "D:\DevTools\Anaconda\envs\yolov8\lib\site-packages\urllib3\connectionpool.py", line 787, in urlopen
    retries = retries.increment(
  File "D:\DevTools\Anaconda\envs\yolov8\lib\site-packages\urllib3\util\retry.py", line 592, in increment
    raise MaxRetryError(_pool, url, error or ResponseError(cause))
urllib3.exceptions.MaxRetryError: HTTPSConnectionPool(host='api.wandb.ai', port=443): Max retries exceeded with url: /graphql (Caused by ConnectTimeoutError(<urllib3.connection.HTTPSConnection object at 0x000001A589FA28B0>, 'Connection to api.wandb.ai timed out. (connect timeout=10)'))

During handling of the above exception, another exception occurred:

Traceback (most recent call last):
  File "D:\DevTools\Anaconda\envs\yolov8\lib\site-packages\wandb\sdk\lib\retry.py", line 131, in __call__
    result = self._call_fn(*args, **kwargs)
  File "D:\DevTools\Anaconda\envs\yolov8\lib\site-packages\wandb\sdk\internal\internal_api.py", line 320, in execute
    return self.client.execute(*args, **kwargs)  # type: ignore
  File "D:\DevTools\Anaconda\envs\yolov8\lib\site-packages\wandb\vendor\gql-0.2.0\wandb_gql\client.py", line 52, in execute
    result = self._get_result(document, *args, **kwargs)
  File "D:\DevTools\Anaconda\envs\yolov8\lib\site-packages\wandb\vendor\gql-0.2.0\wandb_gql\client.py", line 60, in _get_result
    return self.transport.execute(document, *args, **kwargs)
  File "D:\DevTools\Anaconda\envs\yolov8\lib\site-packages\wandb\sdk\lib\gql_request.py", line 55, in execute
    request = self.session.post(self.url, **post_args)
  File "D:\DevTools\Anaconda\envs\yolov8\lib\site-packages\requests\sessions.py", line 635, in post
    return self.request("POST", url, data=data, json=json, **kwargs)
  File "D:\DevTools\Anaconda\envs\yolov8\lib\site-packages\requests\sessions.py", line 587, in request
    resp = self.send(prep, **send_kwargs)
  File "D:\DevTools\Anaconda\envs\yolov8\lib\site-packages\requests\sessions.py", line 701, in send
    r = adapter.send(request, **kwargs)
  File "D:\DevTools\Anaconda\envs\yolov8\lib\site-packages\requests\adapters.py", line 553, in send
    raise ConnectTimeout(e, request=request)
requests.exceptions.ConnectTimeout: HTTPSConnectionPool(host='api.wandb.ai', port=443): Max retries exceeded with url: /graphql (Caused by ConnectTimeoutError(<urllib3.connection.HTTPSConnection object at 0x000001A589FA28B0>, 'Connection to api.wandb.ai timed out. (connect timeout=10)'))
2023-07-11 08:47:45,591 DEBUG   HandlerThread:12080 [handler.py:handle_request():144] handle_request: keepalive
2023-07-11 08:47:50,622 DEBUG   HandlerThread:12080 [handler.py:handle_request():144] handle_request: keepalive
2023-07-11 08:47:55,637 DEBUG   HandlerThread:12080 [handler.py:handle_request():144] handle_request: keepalive
2023-07-11 08:48:00,902 DEBUG   HandlerThread:12080 [handler.py:handle_request():144] handle_request: keepalive
2023-07-11 08:48:02,951 DEBUG   HandlerThread:12080 [handler.py:handle_request():144] handle_request: shutdown
2023-07-11 08:48:02,951 INFO    HandlerThread:12080 [handler.py:finish():854] shutting down handler
2023-07-11 08:48:03,744 INFO    WriterThread:12080 [datastore.py:close():298] close: F:\Project\PythonProject\ultralytics\wandb\run-20230711_084710-k44t7nmw\run-k44t7nmw.wandb
